Failure # 1 (occurred at 2023-06-20_02-59-50)
Traceback (most recent call last):
  File "/opt/conda/lib/python3.10/site-packages/ray/tune/execution/ray_trial_executor.py", line 1231, in get_next_executor_event
    future_result = ray.get(ready_future)
  File "/opt/conda/lib/python3.10/site-packages/ray/_private/client_mode_hook.py", line 105, in wrapper
    return func(*args, **kwargs)
  File "/opt/conda/lib/python3.10/site-packages/ray/_private/worker.py", line 2523, in get
    raise value
ray.exceptions.RayActorError: The actor died because of an error raised in its creation task, [36mray::PPO.__init__()[39m (pid=26077, ip=172.17.0.3, repr=PPO)
  File "/opt/conda/lib/python3.10/site-packages/ray/rllib/evaluation/worker_set.py", line 242, in _setup
    self.add_workers(
  File "/opt/conda/lib/python3.10/site-packages/ray/rllib/evaluation/worker_set.py", line 635, in add_workers
    raise result.get()
  File "/opt/conda/lib/python3.10/site-packages/ray/rllib/utils/actor_manager.py", line 488, in __fetch_result
    result = ray.get(r)
ray.exceptions.RayActorError: The actor died because of an error raised in its creation task, [36mray::RolloutWorker.__init__()[39m (pid=26403, ip=172.17.0.3, repr=<ray.rllib.evaluation.rollout_worker.RolloutWorker object at 0x7fc33b9d14b0>)
  File "/home/BL-Project/black_litterman_env.py", line 112, in reset
    self.weights_memory = [[self.stock1_weight,self.stock2_weight]]
AttributeError: 'BlackLittermanEnv' object has no attribute 'stock1_weight'

The above exception was the direct cause of the following exception:

[36mray::RolloutWorker.__init__()[39m (pid=26403, ip=172.17.0.3, repr=<ray.rllib.evaluation.rollout_worker.RolloutWorker object at 0x7fc33b9d14b0>)
  File "/opt/conda/lib/python3.10/site-packages/ray/rllib/utils/pre_checks/env.py", line 81, in check_env
    check_gym_environments(env)
  File "/opt/conda/lib/python3.10/site-packages/ray/rllib/utils/pre_checks/env.py", line 172, in check_gym_environments
    raise ValueError(
ValueError: Your gymnasium.Env's `reset()` method raised an Exception!

During handling of the above exception, another exception occurred:

[36mray::RolloutWorker.__init__()[39m (pid=26403, ip=172.17.0.3, repr=<ray.rllib.evaluation.rollout_worker.RolloutWorker object at 0x7fc33b9d14b0>)
  File "/opt/conda/lib/python3.10/site-packages/ray/rllib/evaluation/rollout_worker.py", line 616, in __init__
    check_env(self.env)
  File "/opt/conda/lib/python3.10/site-packages/ray/rllib/utils/pre_checks/env.py", line 92, in check_env
    raise ValueError(
ValueError: Traceback (most recent call last):
  File "/opt/conda/lib/python3.10/site-packages/ray/rllib/utils/pre_checks/env.py", line 170, in check_gym_environments
    env.reset()
  File "/home/BL-Project/black_litterman_env.py", line 112, in reset
    self.weights_memory = [[self.stock1_weight,self.stock2_weight]]
AttributeError: 'BlackLittermanEnv' object has no attribute 'stock1_weight'

The above exception was the direct cause of the following exception:

[36mray::RolloutWorker.__init__()[39m (pid=26403, ip=172.17.0.3, repr=<ray.rllib.evaluation.rollout_worker.RolloutWorker object at 0x7fc33b9d14b0>)
  File "/opt/conda/lib/python3.10/site-packages/ray/rllib/utils/pre_checks/env.py", line 81, in check_env
    check_gym_environments(env)
  File "/opt/conda/lib/python3.10/site-packages/ray/rllib/utils/pre_checks/env.py", line 172, in check_gym_environments
    raise ValueError(
ValueError: Your gymnasium.Env's `reset()` method raised an Exception!

The above error has been found in your environment! We've added a module for checking your custom environments. It may cause your experiment to fail if your environment is not set up correctly. You can disable this behavior via calling `config.environment(disable_env_checking=True)`. You can run the environment checking module standalone by calling ray.rllib.utils.check_env([your env]).

During handling of the above exception, another exception occurred:

[36mray::PPO.__init__()[39m (pid=26077, ip=172.17.0.3, repr=PPO)
  File "/opt/conda/lib/python3.10/site-packages/ray/rllib/algorithms/algorithm.py", line 466, in __init__
    super().__init__(
  File "/opt/conda/lib/python3.10/site-packages/ray/tune/trainable/trainable.py", line 169, in __init__
    self.setup(copy.deepcopy(self.config))
  File "/opt/conda/lib/python3.10/site-packages/ray/rllib/algorithms/algorithm.py", line 592, in setup
    self.workers = WorkerSet(
  File "/opt/conda/lib/python3.10/site-packages/ray/rllib/evaluation/worker_set.py", line 194, in __init__
    raise e.args[0].args[2]
ValueError: Traceback (most recent call last):
  File "/opt/conda/lib/python3.10/site-packages/ray/rllib/utils/pre_checks/env.py", line 170, in check_gym_environments
    env.reset()
  File "/home/BL-Project/black_litterman_env.py", line 112, in reset
    self.weights_memory = [[self.stock1_weight,self.stock2_weight]]
AttributeError: 'BlackLittermanEnv' object has no attribute 'stock1_weight'

The above exception was the direct cause of the following exception:

[36mray::PPO.__init__()[39m (pid=26077, ip=172.17.0.3, repr=PPO)
  File "/opt/conda/lib/python3.10/site-packages/ray/rllib/utils/pre_checks/env.py", line 81, in check_env
    check_gym_environments(env)
  File "/opt/conda/lib/python3.10/site-packages/ray/rllib/utils/pre_checks/env.py", line 172, in check_gym_environments
    raise ValueError(
ValueError: Your gymnasium.Env's `reset()` method raised an Exception!

The above error has been found in your environment! We've added a module for checking your custom environments. It may cause your experiment to fail if your environment is not set up correctly. You can disable this behavior via calling `config.environment(disable_env_checking=True)`. You can run the environment checking module standalone by calling ray.rllib.utils.check_env([your env]).

