Failure # 1 (occurred at 2023-06-20_02-51-41)
[36mray::PPO.train()[39m (pid=9854, ip=172.17.0.3, repr=PPO)
  File "/opt/conda/lib/python3.10/site-packages/ray/tune/trainable/trainable.py", line 384, in train
    raise skipped from exception_cause(skipped)
  File "/opt/conda/lib/python3.10/site-packages/ray/tune/trainable/trainable.py", line 381, in train
    result = self.step()
  File "/opt/conda/lib/python3.10/site-packages/ray/rllib/algorithms/algorithm.py", line 792, in step
    results, train_iter_ctx = self._run_one_training_iteration()
  File "/opt/conda/lib/python3.10/site-packages/ray/rllib/algorithms/algorithm.py", line 2811, in _run_one_training_iteration
    results = self.training_step()
  File "/opt/conda/lib/python3.10/site-packages/ray/rllib/algorithms/ppo/ppo.py", line 403, in training_step
    train_batch = synchronous_parallel_sample(
  File "/opt/conda/lib/python3.10/site-packages/ray/rllib/execution/rollout_ops.py", line 85, in synchronous_parallel_sample
    sample_batches = worker_set.foreach_worker(
  File "/opt/conda/lib/python3.10/site-packages/ray/rllib/evaluation/worker_set.py", line 722, in foreach_worker
    handle_remote_call_result_errors(remote_results, self._ignore_worker_failures)
  File "/opt/conda/lib/python3.10/site-packages/ray/rllib/evaluation/worker_set.py", line 75, in handle_remote_call_result_errors
    raise r.get()
ray.exceptions.RayTaskError(AssertionError): [36mray::RolloutWorker.apply()[39m (pid=10207, ip=172.17.0.3, repr=<ray.rllib.evaluation.rollout_worker.RolloutWorker object at 0x7feab2a11540>)
  File "/opt/conda/lib/python3.10/site-packages/ray/rllib/utils/actor_manager.py", line 185, in apply
    raise e
  File "/opt/conda/lib/python3.10/site-packages/ray/rllib/utils/actor_manager.py", line 176, in apply
    return func(self, *args, **kwargs)
  File "/opt/conda/lib/python3.10/site-packages/ray/rllib/execution/rollout_ops.py", line 86, in <lambda>
    lambda w: w.sample(), local_worker=False, healthy_only=True
  File "/opt/conda/lib/python3.10/site-packages/ray/rllib/evaluation/rollout_worker.py", line 915, in sample
    batches = [self.input_reader.next()]
  File "/opt/conda/lib/python3.10/site-packages/ray/rllib/evaluation/sampler.py", line 92, in next
    batches = [self.get_data()]
  File "/opt/conda/lib/python3.10/site-packages/ray/rllib/evaluation/sampler.py", line 277, in get_data
    item = next(self._env_runner)
  File "/opt/conda/lib/python3.10/site-packages/ray/rllib/evaluation/env_runner_v2.py", line 323, in run
    outputs = self.step()
  File "/opt/conda/lib/python3.10/site-packages/ray/rllib/evaluation/env_runner_v2.py", line 349, in step
    active_envs, to_eval, outputs = self._process_observations(
  File "/opt/conda/lib/python3.10/site-packages/ray/rllib/evaluation/env_runner_v2.py", line 678, in _process_observations
    sample_batch = self._try_build_truncated_episode_multi_agent_batch(
  File "/opt/conda/lib/python3.10/site-packages/ray/rllib/evaluation/env_runner_v2.py", line 966, in _try_build_truncated_episode_multi_agent_batch
    assert built_steps + ongoing_steps == self._rollout_fragment_length, (
AssertionError: built_steps (0) + ongoing_steps (1) != rollout_fragment_length (0).
